Workbook
Name _____CLK1: #REF!
Name ____CLK1: #REF!
Name ___CLK1: #REF!
Name ___rrr11: #REF!
Name ___sde098: #REF!
Name __CLK1: #REF!
Name __rrr11: #REF!
Name __sde098: #REF!
Name _0: #REF!
Name _04: #REF!
Name _1: #REF!
Name _10: #REF!
Name _11: #REF!
Name _111: #REF!
Name _115: #REF!
Name _12: #REF!
Name _13: #REF!
Name _14: #REF!
Name _15: #REF!
Name _16: #REF!
Name _17: #REF!
Name _2: #REF!
Name _200: #REF!
Name _201: #REF!
Name _202: #REF!
Name _203: #REF!
Name _204: #REF!
Name _205: #REF!
Name _206: #REF!
Name _207: #REF!
Name _208: #REF!
Name _209: #REF!
Name _210: #REF!
Name _211: #REF!
Name _212: #REF!
Name _213: #REF!
Name _214: #REF!
Name _215: #REF!
Name _216: #REF!
Name _217: #REF!
Name _218: #REF!
Name _219: #REF!
Name _220: #REF!
Name _221: #REF!
Name _222: #REF!
Name _223: #REF!
Name _224: #REF!
Name _225: #REF!
Name _226: #REF!
Name _227: #REF!
Name _228: #REF!
Name _229: #REF!
Name _230: #REF!
Name _231: #REF!
Name _232: #REF!
Name _233: #REF!
Name _234: #REF!
Name _235: #REF!
Name _236: #REF!
Name _237: #REF!

Sheet Title
E3: Project Name: | F3: Conceptual Trade-off Study for Radhikapur West
E5: Block Name: | F5: Radhikapur West
E7: Project No: | F7: IN1411
E9: Client: | F9: VEDANTA LIMITED
E11: Operations: | F11: Opencast Coal Mine
E13: Purpose: | F13: High level Economic Assessment
E15: Included Scenarios: | F15: Option 1- 15 Mtpa; Departmental/ MDO Operation; Coal - Surface Miner; Waste - Truck & Shovel
E17: File: | F17: =MID(CELL("filename",A1),FIND("[",CELL("filename",A1))+1,FIND("]", CELL("filename",A1))-FIND("[",CELL("filename",A1))-1) -> Option 3_15 Mtpa_rev1_smg opt2 quality.xlsx
E21: Project Manager: | F21: Mrinal Kanti Sarkar
E22: Economic Assessment by: | F22: Mrinal Kanti Sarkar; Aniket Banerjee
E23: Reviewer | F23: Somnath Gain; Sudipta De

Sheet Revision
B15: Revision History | C15: Name | D15: Date | E15: Scenario | F15: Comments
B16: 1 | C16: =Title!F17 -> Option 3_15 Mtpa_rev1_smg opt2 quality.xlsx | D16: 16.04.2026 | E16: Scenario 1 | F16: =VLOOKUP(E16,'Scenario Matrix'!$B$4:$F$20,5,FALSE) -> Option 1 - Base Case: Conventional pit progression from in-crop and movement towards dip side
B35: Scenario Matrix
B36: Scenario ID | C36: Mode of Operation | D36: Peak Rated Capacity (Mtpa) | E36: Mining Method | F36: Description
B38: Scenario 1 | C38: Departmental | D38: 15 | E38: Coal - Surface Miner. Waste - Drilling & Blasting | F38: Option 1 - Base Case: Conventional pit progression from in-crop and movement towards dip side | I38: Option 1 - Base Case: Conventional pit progression from in-crop and movement towards dip side
B39: Scenario 2 | C39: MDO/Outsourcing | D39: 15 | E39: Coal - Surface Miner. Waste - Drilling & Blasting | F39: Option 1 - Base Case: Conventional pit progression from in-crop and movement towards dip side | I39: Option 2 - Pit progression following optimizer guided push-backs
B40: Scenario 3 | C40: Departmental | D40: 15 | E40: Coal - Surface Miner. Waste - Drilling & Blasting | F40: Option 2 - Pit progression following optimizer guided push-backs | I40: Option 3 - Two pit strategy; following Grade Distribution of deciding Seam IX – balancing low grade and comparatively high grade
B41: Scenario 4 | C41: MDO/Outsourcing | D41: 15 | E41: Coal - Surface Miner. Waste - Drilling & Blasting | F41: Option 2 - Pit progression following optimizer guided push-backs | I41: Sub variant of Option 2 - Modified for MDO Tender as requested by Vedanta
B42: Scenario 5 | C42: Departmental | D42: 15 | E42: Coal - Surface Miner. Waste - Drilling & Blasting | F42: Option 3 - Two pit strategy; following Grade Distribution of deciding Seam IX – balancing low grade and comparatively high grade
B43: Scenario 6 | C43: MDO/Outsourcing | D43: 15 | E43: Coal - Surface Miner. Waste - Drilling & Blasting | F43: Option 3 - Two pit strategy; following Grade Distribution of deciding Seam IX – balancing low grade and comparatively high grade
B44: Scenario 7 | C44: Departmental | D44: 20 | E44: Coal - Surface Miner. Waste - Drilling & Blasting | F44: Option 1 - Base Case: Conventional pit progression from in-crop and movement towards dip side
B45: Scenario 8 | C45: MDO/Outsourcing | D45: 20 | E45: Coal - Surface Miner. Waste - Drilling & Blasting | F45: Option 1 - Base Case: Conventional pit progression from in-crop and movement towards dip side
B46: Scenario 9 | C46: Departmental | D46: 20 | E46: Coal - Surface Miner. Waste - Drilling & Blasting | F46: Option 2 - Pit progression following optimizer guided push-backs
B47: Scenario 10 | C47: MDO/Outsourcing | D47: 20 | E47: Coal - Surface Miner. Waste - Drilling & Blasting | F47: Option 2 - Pit progression following optimizer guided push-backs
B48: Scenario 11 | C48: Departmental | D48: 20 | E48: Coal - Surface Miner. Waste - Drilling & Blasting | F48: Option 3 - Two pit strategy; following Grade Distribution of deciding Seam IX – balancing low grade and comparatively high grade
B49: Scenario 12 | C49: MDO/Outsourcing | D49: 20 | E49: Coal - Surface Miner. Waste - Drilling & Blasting | F49: Option 3 - Two pit strategy; following Grade Distribution of deciding Seam IX – balancing low grade and comparatively high grade
B50: Scenario 13 | C50: Departmental | D50: 10 | E50: Coal - Surface Miner. Waste - Drilling & Blasting | F50: Sub variant of Option 2 - Modified for MDO Tender as requested by Vedanta
B51: Scenario 14 | C51: MDO/Outsourcing | D51: 10 | E51: Coal - Surface Miner. Waste - Drilling & Blasting | F51: Sub variant of Option 2 - Modified for MDO Tender as requested by Vedanta
B52: Scenario 15 | C52: MDO/Outsourcing | D52: 15 | E52: Drilling & Blasting only | F52: Option 3 - Two pit strategy; following Grade Distribution of deciding Seam IX – balancing low grade and comparatively high grade
B53: Scenario 16 | C53: MDO/Outsourcing | D53: 15 | E53: Drilling & Blasting only | F53: Option 3 - Two pit strategy; following Grade Distribution of deciding Seam IX – balancing low grade and comparatively high grade

Sheet Scenario Matrix
B2: Scenario Matrix
B3: Scenario ID | C3: Mode of Operation | D3: Peak Rated Capacity (Mtpa) | E3: Mining Method | F3: Description
B4: 1 | C4: 2 | D4: 3 | E4: 4 | F4: 5
B5: Scenario 1 | C5: Departmental | D5: 15 | E5: Coal - Surface Miner. Waste - Drilling & Blasting | F5: Option 1 - Base Case: Conventional pit progression from in-crop and movement towards dip side | I5: Option 1 - Base Case: Conventional pit progression from in-crop and movement towards dip side
B6: Scenario 2 | C6: MDO/Outsourcing | D6: 15 | E6: Coal - Surface Miner. Waste - Drilling & Blasting | F6: Option 1 - Base Case: Conventional pit progression from in-crop and movement towards dip side | I6: Option 2 - Pit progression following optimizer guided push-backs
B7: Scenario 3 | C7: Departmental | D7: 15 | E7: Coal - Surface Miner. Waste - Drilling & Blasting | F7: Option 2 - Pit progression following optimizer guided push-backs | I7: Option 3 - Two pit strategy; following Grade Distribution of deciding Seam IX – balancing low grade and comparatively high grade
B8: Scenario 4 | C8: MDO/Outsourcing | D8: 15 | E8: Coal - Surface Miner. Waste - Drilling & Blasting | F8: Option 2 - Pit progression following optimizer guided push-backs | I8: Sub variant of Option 2 - Modified for MDO Tender as requested by Vedanta
B9: Scenario 5 | C9: Departmental | D9: 15 | E9: Coal - Surface Miner. Waste - Drilling & Blasting | F9: Option 3 - Two pit strategy; following Grade Distribution of deciding Seam IX – balancing low grade and comparatively high grade
B10: Scenario 6 | C10: MDO/Outsourcing | D10: 15 | E10: Coal - Surface Miner. Waste - Drilling & Blasting | F10: Option 3 - Two pit strategy; following Grade Distribution of deciding Seam IX – balancing low grade and comparatively high grade
B11: Scenario 7 | C11: Departmental | D11: 20 | E11: Coal - Surface Miner. Waste - Drilling & Blasting | F11: Option 1 - Base Case: Conventional pit progression from in-crop and movement towards dip side
B12: Scenario 8 | C12: MDO/Outsourcing | D12: 20 | E12: Coal - Surface Miner. Waste - Drilling & Blasting | F12: Option 1 - Base Case: Conventional pit progression from in-crop and movement towards dip side
B13: Scenario 9 | C13: Departmental | D13: 20 | E13: Coal - Surface Miner. Waste - Drilling & Blasting | F13: Option 2 - Pit progression following optimizer guided push-backs
B14: Scenario 10 | C14: MDO/Outsourcing | D14: 20 | E14: Coal - Surface Miner. Waste - Drilling & Blasting | F14: Option 2 - Pit progression following optimizer guided push-backs
B15: Scenario 11 | C15: Departmental | D15: 20 | E15: Coal - Surface Miner. Waste - Drilling & Blasting | F15: Option 3 - Two pit strategy; following Grade Distribution of deciding Seam IX – balancing low grade and comparatively high grade
B16: Scenario 12 | C16: MDO/Outsourcing | D16: 20 | E16: Coal - Surface Miner. Waste - Drilling & Blasting | F16: Option 3 - Two pit strategy; following Grade Distribution of deciding Seam IX – balancing low grade and comparatively high grade
B17: Scenario 13 | C17: Departmental | D17: 10 | E17: Coal - Surface Miner. Waste - Drilling & Blasting | F17: Sub variant of Option 2 - Modified for MDO Tender as requested by Vedanta
B18: Scenario 14 | C18: MDO/Outsourcing | D18: 10 | E18: Coal - Surface Miner. Waste - Drilling & Blasting | F18: Sub variant of Option 2 - Modified for MDO Tender as requested by Vedanta
B19: Scenario 15 | C19: MDO/Outsourcing | D19: 15 | E19: Drilling & Blasting only | F19: Option 3 - Two pit strategy; following Grade Distribution of deciding Seam IX – balancing low grade and comparatively high grade
B20: Scenario 16 | C20: MDO/Outsourcing | D20: 15 | E20: Drilling & Blasting only | F20: Option 3 - Two pit strategy; following Grade Distribution of deciding Seam IX – balancing low grade and comparatively high grade

Sheet Disclaimer
C2: Disclaimer & Notice to Reader
C5: The opinions expressed in this Report have been based on the information supplied to SRK Mining Services (India) Pvt. Ltd. (SRK) by Vedanta Limited. The opinions in this Report are provided in response to a specific request from Vedanta to do so. SRK has exercised all due care in reviewing the supplied information. Whilst SRK has compared key supplied data with expected values, the accuracy of the results and conclusions from the review are entirely reliant on the accuracy and completeness of the supplied data. SRK does not accept responsibility for any errors or omissions in the supplied information and does not accept any consequential liability arising from commercial decisions or actions resulting from them. Opinions presented in this report apply to the site conditions and features as they existed at the time of SRK’s investigations, and those reasonably foreseeable. These opinions do not necessarily apply to conditions and features that may arise after the date of this Report, about which SRK had no prior knowledge nor had the opportunity to evaluate. Opinions expressed in this document can significantly vary based on specific site conditions, project technicalities and engineering designs, decided through an appropriate technical works. If this document is disclosed or distributed to any third party, no such third party shall be entitled to place reliance upon any information, warranties or representations which may be contained within this document and the Recipients of this document shall indemnify SRK against all and any claims, losses and costs which may be incurred by SRK relating to such third parties There is a wide range of modifying factors – including increasingly important social and environmental impacts – that mining projects had to explore and mitigate before a mine’s viability could be fully assessed. Given the nature of the mandate, multiple best guess assumptions are taken, in most cases in consultation with the company, to assess impact which undoubtedly needs to be validated in future and through a full feasibility study before any production decisions are made.

Sheet Guide
C3: Description | D3: Status
B4: Tab Colors
B5: Yellow | C5: Title, Revision History, Disclaimer and Guide
B6: Purple | C6: Charts
B7: Red | C7: Summary
B8: Green | C8: Inputs/Quotes
B9: Blue | C9: Calculation Sheets (do not type in these tabs)
B10: Cell Colors
B11: Blue | C11: Links to another tab
B12: Red | C12: Hard Input
B13: Black | C13: Calculation using links from current tab
B14: Pink | C14: Links to external file
B15: Green | C15: Calculation using Named Values/Arrays
B16: Black | C16: Drop down Cell
B17: Grey | C17: Not required/No data

Sheet Assumptions_Dashboard
B2: Basic Considerations | K2: Coal Mining Machinery | L2: Surface Miner | M2: Surface Miner | P2: LOM Opex
B3: General considerations | C3: Unit | D3: Value | E3: Basis | L3: P-IRR | M3: Shovel & Dumper | P3: Sl No | Q3: List | R3: Unit | S3: Total
B4: Project Start Date | C4: date | D4: 45627 | E4: Standard Assumption based on Vesting Order | K4: Mining Operation | L4: Departmental | M4: MDO | P4: 1 | Q4: ='Project OPEX'!B13 -> MDO/ Contractor Cost | R4: ='Project OPEX'!C13 -> INR/t | S4: ='Project OPEX'!D13 -> 0
B5: Effective Start Date for Model | C5: date | D5: 46023 | M5: Departmental | Q5: Pit Head cost
B6: Production Start Date | C6: date | D6: 47119 | E6: Standard Assumption based on CMDPA | K6: Pre Tax & Pre Finance Basis | L6: Yes | P6: =P4+1 -> 2 | Q6: HEMM Consumable | R6: INR/t | S6: =SUM('Project OPEX'!D15:D18) -> 196.2501
B7: Production Starting Year | C7: No. | D7: 5 | P7: =P6+1 -> 3 | Q7: ='Project OPEX'!B19 -> CHP | R7: INR/t | S7: ='Project OPEX'!D19 -> 9.7551601
B8: Total Coal | C8: Mt | D8: ='Production Schedule'!D5 -> 225.70441 | E8: Estimated from Design | K8: Coal Price | L8: Commercial | P8: =P7+1 -> 4 | Q8: ='Project OPEX'!B20 -> Power | R8: INR/t | S8: ='Project OPEX'!D20 -> 10.001119
B9: Total Waste | C9: Mbcm | D9: ='Production Schedule'!D8 -> 535.39467 | E9: Estimated from Design | P9: =P8+1 -> 5 | Q9: ='Project OPEX'!B69 -> Owner Wage | R9: INR/t | S9: ='Project OPEX'!D23 -> 41.628474
B10: Rated Capacity | C10: Mtpa | D10: =MAX('Production Schedule'!E5:AM5) -> 15.000016 | E10: Mutual Discussion with Company | K10: Price co-relation factor (NCI to Commercial) | L10: 1.6 | P10: =P9+1 -> 6 | Q10: ='Project OPEX'!B70 -> Explosives | R10: INR/t | S10: ='Project OPEX'!D24 -> 56.413078
B11: Production in 1st year | C11: Mt | D11: ='Production Schedule'!I5 -> 1.9999998 | E11: Estimated from Design | P11: =P10+1 -> 7 | Q11: ='Project OPEX'!B71 -> Civil Infrastructure Maintenance | R11: INR/t | S11: ='Project OPEX'!D25 -> 4.019638
B12: Life of Mine | C12: Year | D12: =MAX('Production Schedule'!E3:AM3) -> 19 | E12: Estimated from Design | P12: =P11+1 -> 8 | Q12: ='Project OPEX'!B72 -> Railway Track & Siding Repair & Maintenance | R12: INR/t | S12: ='Project OPEX'!D26 -> 15.91019
B13: Block Area | C13: ha | D13: 1048 | E13: As per Tender | J13: Initial Capital Costs (Owner) | P13: =P12+1 -> 9 | Q13: ='Project OPEX'!B73 -> Fire Fighting & Dust Suppression | R13: INR/t | S13: ='Project OPEX'!D27 -> 0.4257449
B14: Working Regime | J14: Sl No | K14: List | L14: Unit | M14: Total | N14: % | P14: =P13+1 -> 10 | Q14: ='Project OPEX'!B74 -> Rehandling | R14: INR/t | S14: ='Project OPEX'!D28 -> 23.459001
B15: Description | C15: Units | D15: Values | E15: Basis | J15: 1 | K15: ='Owner CAPEX'!B11 -> Pre-operative costs | L15: INR Cr | M15: ='Owner CAPEX'!D11 -> 214.12704 | N15: =M15/$M$30 -> 0.044304252 | P15: =P14+1 -> 11 | Q15: ='Project OPEX'!B75 -> Digitalization (AMC) | R15: INR/t | S15: ='Project OPEX'!D29 -> 0.29463315
B16: Number of Shifts/day | C16: Nos. | D16: 3 | E16: Standard Assumption | J16: =J15+1 -> 2 | K16: ='Owner CAPEX'!B12 -> Upfront Amount | L16: INR Cr | M16: ='Owner CAPEX'!D12 -> 99.07 | N16: =M16/$M$30 -> 0.020498216 | P16: =P15+1 -> 12 | Q16: ='Project OPEX'!B76 -> Environment Management & OHS costs | R16: INR/t | S16: ='Project OPEX'!D30 -> 2.6937888
B17: Hours/ Shift | C17: hrs | D17: 8 | J17: =J16+1 -> 3 | K17: ='Owner CAPEX'!B13 -> Land Cost | L17: INR Cr | M17: ='Owner CAPEX'!D13 -> 985.07802 | N17: =M17/$M$30 -> 0.20381893 | P17: =P16+1 -> 13 | Q17: ='Project OPEX'!B77 -> Canteen, Accommodation, Laundry, Vehicle etc. Cost | R17: INR/t | S17: ='Project OPEX'!D31 -> 0.12344686
B18: Delays & Refreshment | C18: hrs | D18: 0 | E18: Considered in Utilization % | J18: =J17+1 -> 4 | K18: ='Owner CAPEX'!B14 -> R&R Cost | L18: INR Cr | M18: ='Owner CAPEX'!D14 -> 1048.57 | N18: =M18/$M$30 -> 0.21695584 | P18: =P17+1 -> 14 | Q18: ='Project OPEX'!B78 -> Admin and Overhead | R18: INR/t | S18: ='Project OPEX'!D32 -> 15
B19: Actual Hours/ Shift | C19: hrs | D19: =D17-D18 -> 8 | E19: Standard Assumption | J19: =J18+1 -> 5 | K19: ='Owner CAPEX'!B15 -> HEMM Equipment | L19: INR Cr | M19: ='Owner CAPEX'!D15 -> 701.51584 | N19: =M19/$M$30 -> 0.14514811 | P19: =P18+1 -> 15 | Q19: ='Project OPEX'!B79 -> R&R (Resettlement & Rehabilitation) | R19: INR/t | S19: ='Project OPEX'!D33 -> 3.2669141
B20: Calendar Days | C20: Days | D20: 365 | E20: Standard Assumption | J20: =J19+1 -> 6 | K20: ='Owner CAPEX'!B16 -> CHP | L20: INR Cr | M20: ='Owner CAPEX'!D16 -> 335.19 | N20: =M20/$M$30 -> 0.069352952 | P20: =P19+1 -> 16 | Q20: ='Project OPEX'!B80 -> Contingency | R20: INR/t | S20: ='Project OPEX'!D34 -> 56.886193
B21: National Holidays | C21: Days | D21: 8 | E21: Standard Assumption | J21: =J20+1 -> 7 | K21: ='Owner CAPEX'!B17 -> Railway Siding | L21: INR Cr | M21: ='Owner CAPEX'!D17 -> 540 | N21: =M21/$M$30 -> 0.11172945 | Q21: Subtotal | R21: INR/t | S21: =SUM(S6:S20) -> 436.12748
B22: Festival Impact | C22: Days | D22: =1+1 -> 2 | E22: Impacted attendence due to festival | J22: =J21+1 -> 8 | K22: ='Owner CAPEX'!B18 -> Civil Infrastructure | L22: INR Cr | M22: ='Owner CAPEX'!D18 -> 191 | N22: =M22/$M$30 -> 0.03951912 | Q22: Government Fees & Charges | R22: INR/t
B23: Available Days | C23: Days | D23: =D20-D21-D22 -> 355 | E23: Derived | J23: =J22+1 -> 9 | K23: ='Owner CAPEX'!B19 -> Fire Fighting & Dust Suppression | L23: INR Cr | M23: ='Owner CAPEX'!D19 -> 14.45 | N23: =M23/$M$30 -> 0.0029897973 | P23: =P20+1 -> 17 | Q23: ='Project OPEX'!B37 -> Revenue Sharing | R23: INR/t | S23: ='Project OPEX'!D37 -> 204.54301
B24: Extreme Summer Impact | C24: Days | D24: =(30*4)/24 -> 5 | E24: 30days of extreme heat consider with no work of 4 hours in day (11am to 3pm) | G24: =M30 -> 4833.1036 | I24: INR Cr | J24: =J23+1 -> 10 | K24: ='Owner CAPEX'!B20 -> Workshop and Store | L24: INR Cr | M24: ='Owner CAPEX'!D20 -> 27.27 | N24: =M24/$M$30 -> 0.0056423372 | P24: =P23+1 -> 18 | Q24: ='Project OPEX'!B38 -> GST on Revenue Sharing | R24: INR/t | S24: ='Project OPEX'!D38 -> 36.817742
B25: Number of Moonsoon Month having heavy rainfall | C25: Months | D25: 2 | E25: Standard Assumption | J25: =J24+1 -> 11 | K25: ='Owner CAPEX'!B21 -> Electrical | L25: INR Cr | M25: ='Owner CAPEX'!D21 -> 34.35 | N25: =M25/$M$30 -> 0.0071072344 | P25: =P24+1 -> 19 | Q25: ='Project OPEX'!B39 -> Royalty (% of NCI notified Price) | R25: INR/t | S25: ='Project OPEX'!D39 -> 139.28825
B26: Hours loss per day in Moonsoon Month | C26: hrs/day | D26: 8 | E26: Standard Assumption | J26: =J25+1 -> 12 | K26: ='Owner CAPEX'!B22 -> Mine Dewatering System | L26: INR Cr | M26: ='Owner CAPEX'!D22 -> 15 | N26: =M26/$M$30 -> 0.0031035958 | P26: =P25+1 -> 20 | Q26: ='Project OPEX'!B40 -> DMF (District Mineral Foundation) | R26: INR/t | S26: ='Project OPEX'!D40 -> 13.928825
B27: Days loss due to rain | C27: Days | D27: =((D25*30)*D26)/24 -> 20 | E27: Derived | J27: =J26+1 -> 13 | K27: ='Owner CAPEX'!B23 -> Digitalisation | L27: INR Cr | M27: ='Owner CAPEX'!D23 -> 10 | N27: =M27/$M$30 -> 0.0020690639 | P27: =P26+1 -> 21 | Q27: ='Project OPEX'!B41 -> NMET (National Mineral Exploration Trust) | R27: INR/t | S27: ='Project OPEX'!D41 -> 4.1786476
B28: Working days | C28: Days | D28: =D23-D24-D27 -> 330 | E28: Derived | J28: =J27+1 -> 14 | K28: ='Owner CAPEX'!B24 -> Contingency | L28: INR Cr | M28: ='Owner CAPEX'!D24 -> 617.48264 | N28: =M28/$M$30 -> 0.1277611 | P28: =P27+1 -> 22 | Q28: ='Project OPEX'!B42 -> Surface Rent | R28: INR/t | S28: ='Project OPEX'!D42 -> 0.17644317
B29: Total available Hours | C29: hrs | D29: =D28*D16*$D$19 -> 7920 | E29: Derived | J29: =J28+1 -> 15 | K29: ='Owner CAPEX'!B25 -> IDC | L29: INR Cr | M29: ='Owner CAPEX'!D25 -> 0 | N29: =M29/$M$30 -> 0 | P29: =P28+1 -> 23 | Q29: ='Project OPEX'!B43 -> GST on Royalty, DMF, NMET, etc | R29: INR/t | S29: ='Project OPEX'!D43 -> 28.362991
B30: Density & Swell Factor | K30: Total Initial Capital Expenditure | L30: INR Cr | M30: =SUM(M15:M29) -> 4833.1036 | P30: =P29+1 -> 24 | Q30: ='Project OPEX'!B44 -> Progressive Mine Closure Costs | R30: INR/t | S30: ='Project OPEX'!D44 -> 12.963778
B31: Description | C31: Unit | D31: Value | E31: Basis | P31: =P30+1 -> 25 | Q31: ='Project OPEX'!B45 -> Bank Fee on PBG | R31: INR/t | S31: ='Project OPEX'!D45 -> 2.2153887
B32: Average density of Coal | C32: t/cum | D32: 1.72 | E32: In-situ Density | J32: Sl No | K32: List | L32: Unit | M32: Value | P32: =P31+1 -> 26 | Q32: Subtotal | R32: INR/t | S32: =SUM(S23:S31) -> 442.47508
B33: Average density of Waste | C33: t/cum | D33: 2.1 | E33: In-situ Density | J33: 1 | K33: =CF!C40 -> Equity IRR | L33: % | M33: =CF!D40 -> 0.15815964 | Q33: Total Initial Capital Expenditure | R33: INR Cr | S33: =S4+S21+S32 -> 878.60256
B34: Swell factor for Coal | C34: % | D34: 0.2 | J34: 2 | K34: =CF!C41 -> Equity NPV | L34: INR CR | M34: =CF!D41 -> 900.32264 | R34: INR/kcal | S34: ='Project OPEX'!D54 -> 0.28220195
B35: Swell factor for Waste | C35: % | D35: 0.2
B36: Salary & Wages | J36: 3 | K36: =CF!C18 -> Project IRR | L36: % | M36: =CF!D18 -> 0.15815964
B37: Category wise Executives wage details | C37: Category | D37: Annual CTC | E37: Basis | J37: 4 | K37: =CF!C19 -> Project NPV | L37: INR CR | M37: =CF!D19 -> 900.32264
B38: Project Head/ Vice-President | C38: E9 | D38: 6000000 | E38: SRK Assumption
B39: Vice-President/Chief General Manager | C39: E8 | D39: 4500000 | E39: SRK Assumption
B40: General Manager | C40: E7 | D40: 4000000 | E40: SRK Assumption
B41: Deputy General Manager | C41: E6 | D41: 3500000 | E41: SRK Assumption
...

Sheet Production Schedule
E1: =Assumptions_Dashboard!$D$5 -> 46023 | F1: =E1+366 -> 46389 | G1: =F1+366 -> 46755 | H1: =G1+366 -> 47121 | I1: =H1+366 -> 47487 | J1: =I1+366 -> 47853 | K1: =J1+366 -> 48219 | L1: =K1+366 -> 48585 | M1: =L1+366 -> 48951 | ... AA1: =Z1+366 -> 54075
A2: 1. Working Hours | E2: 1 | F2: =IF(MAX($E$2:E$2)<=(Assumptions_Dashboard!$D$11+Assumptions_Dashboard!$D$6-2),E$2+1,0) -> 2 | G2: =IF(MAX($E$2:F$2)<=(Assumptions_Dashboard!$D$11+Assumptions_Dashboard!$D$6-2),F$2+1,0) -> 3 | H2: =IF(MAX($E$2:G$2)<=(Assumptions_Dashboard!$D$11+Assumptions_Dashboard!$D$6-2),G$2+1,0) -> 4 | I2: =IF(MAX($E$2:H$2)<=(Assumptions_Dashboard!$D$11+Assumptions_Dashboard!$D$6-2),H$2+1,0) -> 5 | J2: =IF(MAX($E$2:I$2)<=(Assumptions_Dashboard!$D$11+Assumptions_Dashboard!$D$6-2),I$2+1,0) -> 6 | K2: =IF(MAX($E$2:J$2)<=(Assumptions_Dashboard!$D$11+Assumptions_Dashboard!$D$6-2),J$2+1,0) -> 7 | L2: =IF(MAX($E$2:K$2)<=(Assumptions_Dashboard!$D$11+Assumptions_Dashboard!$D$6-2),K$2+1,0) -> 8 | M2: =IF(MAX($E$2:L$2)<=(Assumptions_Dashboard!$D$11+Assumptions_Dashboard!$D$6-2),L$2+1,0) -> 9 | ... AA2: =IF(MAX($E$2:Z$2)<=(Assumptions_Dashboard!$D$11+Assumptions_Dashboard!$D$6-2),Z$2+1,0) -> 23
B3: Description | C3: Units | D3: Total/ Average | E3: =IF(E2=0,0,IF((E$2-Assumptions_Dashboard!$D$7)<0,E$2-Assumptions_Dashboard!$D$7,E$2-(Assumptions_Dashboard!$D$7-1))) -> -4 | F3: =IF(F2=0,0,IF((F$2-Assumptions_Dashboard!$D$7)<0,F$2-Assumptions_Dashboard!$D$7,F$2-(Assumptions_Dashboard!$D$7-1))) -> -3 | G3: =IF(G2=0,0,IF((G$2-Assumptions_Dashboard!$D$7)<0,G$2-Assumptions_Dashboard!$D$7,G$2-(Assumptions_Dashboard!$D$7-1))) -> -2 | H3: =IF(H2=0,0,IF((H$2-Assumptions_Dashboard!$D$7)<0,H$2-Assumptions_Dashboard!$D$7,H$2-(Assumptions_Dashboard!$D$7-1))) -> -1 | I3: =IF(I2=0,0,IF((I$2-Assumptions_Dashboard!$D$7)<0,I$2-Assumptions_Dashboard!$D$7,I$2-(Assumptions_Dashboard!$D$7-1))) -> 1 | J3: =IF(J2=0,0,IF((J$2-Assumptions_Dashboard!$D$7)<0,J$2-Assumptions_Dashboard!$D$7,J$2-(Assumptions_Dashboard!$D$7-1))) -> 2 | K3: =IF(K2=0,0,IF((K$2-Assumptions_Dashboard!$D$7)<0,K$2-Assumptions_Dashboard!$D$7,K$2-(Assumptions_Dashboard!$D$7-1))) -> 3 | L3: =IF(L2=0,0,IF((L$2-Assumptions_Dashboard!$D$7)<0,L$2-Assumptions_Dashboard!$D$7,L$2-(Assumptions_Dashboard!$D$7-1))) -> 4 | ... AA3: =IF(AA2=0,0,IF((AA$2-Assumptions_Dashboard!$D$7)<0,AA$2-Assumptions_Dashboard!$D$7,AA$2-(Assumptions_Dashboard!$D$7-1))) -> 19
B4: Total available Hours excavation | C4: hrs | D4: =MAX(E4:AD4) -> 7920 | E4: =IF(E$3<=0,0,Assumptions_Dashboard!$D$29) -> 0 | F4: =IF(F$3<=0,0,Assumptions_Dashboard!$D$29) -> 0 | G4: =IF(G$3<=0,0,Assumptions_Dashboard!$D$29) -> 0 | H4: =IF(H$3<=0,0,Assumptions_Dashboard!$D$29) -> 0 | I4: =IF(I$3<=0,0,Assumptions_Dashboard!$D$29) -> 7920 | J4: =IF(J$3<=0,0,Assumptions_Dashboard!$D$29) -> 7920 | K4: =IF(K$3<=0,0,Assumptions_Dashboard!$D$29) -> 7920 | L4: =IF(L$3<=0,0,Assumptions_Dashboard!$D$29) -> 7920 | ... AA4: =IF(AA$3<=0,0,Assumptions_Dashboard!$D$29) -> 7920
B5: Production Coal/Ore | C5: Mt | D5: =SUM(E5:AA5) -> 225.70441 | I5: {=TRANSPOSE(K42:K60)} -> 1.9999998 | J5: 3.9999987 | K5: 8.0000007 | L5: 11.999999 | M5: 14.999995 | N5: 15.000007 | O5: 14.999999 | P5: 14.999997 | Q5: 15.000004 | R5: 14.999995 | S5: 14.999997 | T5: 15.000002 | U5: 15.000016 | V5: 15.000002 | W5: 15.000002 | X5: 15 | Y5: 9.9999996 | Z5: 7.5000027 | AA5: 2.2043909
A6: =IF(Assumptions_Dashboard!L2="Surface Miner",Assumptions_Dashboard!D81,100%) -> 0.15 | B6: Blasted Coal/Ore | C6: Mt | D6: =SUM(E6:AA6) -> 38.95566 | I6: =IF(Assumptions_Dashboard!$D$80>=I3,I5,I5*$A$6) -> 1.9999998 | J6: =IF(Assumptions_Dashboard!$D$80>=J3,J5,J5*$A$6) -> 3.9999987 | K6: =IF(Assumptions_Dashboard!$D$80>=K3,K5,K5*$A$6) -> 1.2000001 | L6: =IF(Assumptions_Dashboard!$D$80>=L3,L5,L5*$A$6) -> 1.7999998 | M6: =IF(Assumptions_Dashboard!$D$80>=M3,M5,M5*$A$6) -> 2.2499993 | N6: =IF(Assumptions_Dashboard!$D$80>=N3,N5,N5*$A$6) -> 2.2500011 | O6: =IF(Assumptions_Dashboard!$D$80>=O3,O5,O5*$A$6) -> 2.2499998 | P6: =IF(Assumptions_Dashboard!$D$80>=P3,P5,P5*$A$6) -> 2.2499995 | ... AA6: =IF(Assumptions_Dashboard!$D$80>=AA3,AA5,AA5*$A$6) -> 0.33065864
B7: Surface Miner Coal/Ore | C7: Mt | D7: =SUM(E7:AA7) -> 186.74875 | I7: =I5-I6 -> 0 | J7: =J5-J6 -> 0 | K7: =K5-K6 -> 6.8000006 | L7: =L5-L6 -> 10.199999 | M7: =M5-M6 -> 12.749996 | N7: =N5-N6 -> 12.750006 | O7: =O5-O6 -> 12.749999 | P7: =P5-P6 -> 12.749997 | ... AA7: =AA5-AA6 -> 1.8737323
B8: Waste (Topsoil + Overburden + Interburden) | C8: Mbcm | D8: =SUM(E8:AA8) -> 535.39467 | I8: {=TRANSPOSE(O42:O60)} -> 11.466046 | J8: 9.5178188 | K8: 17.240515 | L8: 36.817196 | M8: 35.420575 | N8: 47.463611 | O8: 43.447467 | P8: 36.337475 | Q8: 37.865192 | R8: 33.778948 | S8: 38.053482 | T8: 28.983165 | U8: 25.44988 | V8: 31.615551 | W8: 31.515275 | X8: 40.123367 | Y8: 24.726595 | Z8: 4.2960407 | AA8: 1.2764738
B9: Top Soil | C9: Mbcm | D9: =SUM(E9:AO9) -> 1.6670317 | I9: 0.061151145 | J9: 0.086432905 | K9: 0.1789022 | L9: 0.20884342 | M9: 0.16172259 | N9: 0.094374156 | O9: 0.094374156 | P9: 0.094374156 | Q9: 0.094374156 | R9: 0.094374156 | S9: 0.0582654 | T9: 0.0582654 | U9: 0.0582654 | V9: 0.0582654 | W9: 0.0582654 | X9: 0.051695409 | Y9: 0.051695409 | Z9: 0.051695409 | AA9: 0.051695409
B10: OB | C10: Mbcm | D10: =SUM(E10:AA10) -> 121.47374 | I10: =I8-I9-I11 -> 2.5760394 | J10: =J8-J9-J11 -> 2.1026654 | K10: =K8-K9-K11 -> 3.7864162 | L10: =L8-L9-L11 -> 8.2591117 | M10: =M8-M9-M11 -> 7.9850096 | N10: =N8-N9-N11 -> 10.822256 | O10: =O8-O9-O11 -> 9.8985433 | P10: =P8-P9-P11 -> 8.2632451 | ... AA10: =AA8-AA9-AA11 -> 0.24189357
A11: 0.77 | B11: Partings | C11: Mbcm | D11: =SUM(E11:AA11) -> 412.2539 | I11: =I8*$A$11 -> 8.8288552 | J11: =J8*$A$11 -> 7.3287205 | K11: =K8*$A$11 -> 13.275197 | L11: =L8*$A$11 -> 28.349241 | M11: =M8*$A$11 -> 27.273843 | N11: =N8*$A$11 -> 36.546981 | O11: =O8*$A$11 -> 33.45455 | P11: =P8*$A$11 -> 27.979856 | ... AA11: =AA8*$A$11 -> 0.98288486
A12: 0.05 | B12: Rehandling at CHP | C12: Mbcm | D12: =SUM(E12:AA12) -> 6.5611746 | I12: =I5/Assumptions_Dashboard!$D$32*$A$12 -> 0.058139528 | J12: =J5/Assumptions_Dashboard!$D$32*$A$12 -> 0.11627903 | K12: =K5/Assumptions_Dashboard!$D$32*$A$12 -> 0.23255816 | L12: =L5/Assumptions_Dashboard!$D$32*$A$12 -> 0.34883717 | M12: =M5/Assumptions_Dashboard!$D$32*$A$12 -> 0.43604637 | N12: =N5/Assumptions_Dashboard!$D$32*$A$12 -> 0.43604672 | O12: =O5/Assumptions_Dashboard!$D$32*$A$12 -> 0.43604647 | P12: =P5/Assumptions_Dashboard!$D$32*$A$12 -> 0.43604642 | ... AA12: =AA5/Assumptions_Dashboard!$D$32*$A$12 -> 0.064081132
B13: Waste - Rehandle | C13: Mbcm | D13: =SUM(E13:AO13) -> 75.64 | O13: 11.85 | P13: 11.85 | Q13: 11.85 | R13: 11.85 | S13: 7.06 | T13: 7.06 | U13: 7.06 | V13: 7.06
B14: GCV (ADB) | C14: kcal/kg | D14: =SUMPRODUCT(E5:AA5,E14:AA14)/D5 -> 3113.3823 | I14: {=TRANSPOSE(M42:M60)} -> 3210 | J14: 3150 | K14: 3160 | L14: 3150 | M14: 3120 | N14: 3190 | O14: 3090 | P14: 3160 | Q14: 3190 | R14: 3280 | S14: 3280 | T14: 3020 | U14: 3120 | V14: 3100 | W14: 2850 | X14: 2970 | Y14: 3020 | Z14: 3040 | AA14: 3200
B15: Relaive Density (RD) | C15: g/cm²
B16: Raw ash | C16: %
B17: Moisture | C17: %
B18: Stripping Ratio
B19: YoY | C19: cum/t | I19: =I8/I5 -> 5.7330236 | J19: =J8/J5 -> 2.3794555 | K19: =K8/K5 -> 2.1550642 | L19: =L8/L5 -> 3.0681001 | M19: =M8/M5 -> 2.3613724 | N19: =N8/N5 -> 3.1642392 | O19: =O8/O5 -> 2.8964981 | P19: =P8/P5 -> 2.4224988 | ... AA19: =AA8/AA5 -> 0.57905965
B20: Cumulative | C20: cum/t | D20: =D8/D5 -> 2.3721055 | I20: =I8/I5 -> 5.7330236 | J20: =SUM($I$8:J8)/SUM($I$5:J5) -> 3.4973117 | K20: =SUM($I$8:K8)/SUM($I$5:K5) -> 2.730313 | L20: =SUM($I$8:L8)/SUM($I$5:L5) -> 2.8862147 | M20: =SUM($I$8:M8)/SUM($I$5:M5) -> 2.6941993 | N20: =SUM($I$8:N8)/SUM($I$5:N5) -> 2.8201029 | O20: =SUM($I$8:O8)/SUM($I$5:O5) -> 2.8362427 | P20: =SUM($I$8:P8)/SUM($I$5:P5) -> 2.7640781 | Q20: =SUM($I$8:Q8)/SUM($I$5:Q5) -> 2.7284742 | ... AA20: =SUM($I$8:AA8)/SUM($I$5:AA5) -> 2.3721055
B22: Haul Distance
B23: ROM | C23: km | D23: =SUMPRODUCT(I23:AH23,I5:AH5)/SUM(I5:AH5) -> 3.488188 | I23: 1.6 | J23: 1.6 | K23: 2 | L23: 2.5 | M23: 2.6 | N23: 2.8 | O23: 3 | P23: 3.2 | Q23: 3.4 | R23: 3.5 | S23: 3.7 | T23: 3.8 | U23: 4 | V23: 4.2 | W23: 4.4 | X23: 4.4 | Y23: 4.4 | Z23: 4.4 | AA23: 4.4
B24: Waste | C24: km | D24: =SUMPRODUCT(I24:AH24,I8:AH8)/SUM(I8:AH8) -> 1.7159833 | I24: 1.475764 | J24: 1.8169713 | K24: 1.7860172 | L24: 1.5927861 | M24: 1.2863679 | N24: 1.4290943 | O24: 1.5718207 | P24: 1.7145471 | Q24: 1.8572736 | R24: 2 | S24: 1.96 | T24: 1.92 | U24: 1.88 | V24: 1.84 | W24: 1.8 | X24: 1.74 | Y24: 1.68 | Z24: 1.62 | AA24: 1.5
B25: In-Pit | C25: km | L25: 0.8 | M25: 1 | N25: 1.4290943 | O25: 1.5718207 | P25: 1.7145471 | Q25: 1.8572736 | R25: 2 | S25: 1.96 | T25: 1.92 | U25: 1.88 | V25: 1.84 | W25: 1.8 | X25: 1.74 | Y25: 1.68 | Z25: 1.62 | AA25: 1.5
B26: Ex-Pit | C26: km | I26: 1.475764 | J26: 1.8169713 | K26: 1.7860172 | L26: 1.8 | M26: 1.8
B27: Rehandling | C27: km | O27: 3 | P27: 3 | Q27: 3 | R27: 3 | S27: 3 | T27: 3 | U27: 3 | V27: 3
B29: Bench Specification
B30: Bench Height - Coal | C30: m | D30: 5
B31: Bench Width - Coal | C31: m | D31: 20
B32: Bench Height - OB/IB | C32: m | D32: 10
B33: Bench Width - OB/IB | C33: m | D33: 20
B35: Rehandling cost | C35: INR Cr | D35: =SUM(E35:AH35) -> 529.48 | E35: =Assumptions_Dashboard!$D$153*E13/10 -> 0 | F35: =Assumptions_Dashboard!$D$153*F13/10 -> 0 | G35: =Assumptions_Dashboard!$D$153*G13/10 -> 0 | H35: =Assumptions_Dashboard!$D$153*H13/10 -> 0 | I35: =Assumptions_Dashboard!$D$153*I13/10 -> 0 | J35: =Assumptions_Dashboard!$D$153*J13/10 -> 0 | K35: =Assumptions_Dashboard!$D$153*K13/10 -> 0 | L35: =Assumptions_Dashboard!$D$153*L13/10 -> 0 | ... AA35: =Assumptions_Dashboard!$D$153*AA13/10 -> 0
L40: Diluted | M40: Rounded | N40: Cumulative
J41: Year | K41: Coal (Mt) | L41: GCV Dil (Kcal/Kg) | M41: GCV Dil (Kcal/Kg) | N41: Coal (Mt) | O41: Waste (Mcum)
J42: 1 | K42: 1.9999998 | L42: 3210 | M42: =ROUND(L42,-1) -> 3210 | N42: =K42 -> 1.9999998 | O42: 11.466046
J43: =J42+1 -> 2 | K43: 3.9999987 | L43: 3150 | M43: =ROUND(L43,-1) -> 3150 | N43: =N42+K43 -> 5.9999984 | O43: 9.5178188
J44: =J43+1 -> 3 | K44: 8.0000007 | L44: 3160 | M44: =ROUND(L44,-1) -> 3160 | N44: =N43+K44 -> 13.999999 | O44: 17.240515
J45: =J44+1 -> 4 | K45: 11.999999 | L45: 3150 | M45: =ROUND(L45,-1) -> 3150 | N45: =N44+K45 -> 25.999998 | O45: 36.817196
J46: =J45+1 -> 5 | K46: 14.999995 | L46: 3120 | M46: =ROUND(L46,-1) -> 3120 | N46: =N45+K46 -> 40.999993 | O46: 35.420575
J47: =J46+1 -> 6 | K47: 15.000007 | L47: 3190 | M47: =ROUND(L47,-1) -> 3190 | N47: =N46+K47 -> 56 | O47: 47.463611
...

Sheet Sensitivity
B2: Sensitivity
B3: Parameters | C3: % Change | Q3: %Change in Coal Selling Price | R3: Equity IRR | S3: Project IRR | T3: Project NPV | U3: Equity NPV
B4: Capex | C4: 0 | R4: 0.11436347 | S4: 0.1132572 | T4: 316.35859 | U4: 301.84625
B5: Opex | C5: 0 | Q5: -0.2 | R5: 0.072989795 | S5: 0.076714511 | T5: -503.93299 | U5: -518.44533
B6: Coal Price | C6: 0 | Q6: -0.15 | R6: 0.084183611 | S6: 0.086651723 | T6: -296.79548 | U6: -311.30782
Q7: -0.1 | R7: 0.094697914 | S7: 0.095951181 | T7: -92.333856 | U7: -106.8462
Q8: -0.05 | R8: 0.10473416 | S8: 0.1047977 | T8: 112.01237 | U8: 97.500024
Q9: 0 | R9: 0.11436347 | S9: 0.1132572 | T9: 316.35859 | U9: 301.84625
Q10: 0.05 | R10: 0.12363789 | S10: 0.1213785 | T10: 520.70481 | U10: 506.19247
B11: GST on Revenue Sharing | C11: Yes | Q11: 0.1 | R11: 0.13259898 | S11: 0.12920097 | T11: 725.05103 | U11: 710.53869
C12: P-IRR | D12: E-IRR | Q12: 0.15 | R12: 0.14128044 | S12: 0.13675686 | T12: 929.39725 | U12: 914.88491
Q13: 0.2 | R13: 0.14970998 | S13: 0.14407296 | T13: 1133.7435 | U13: 1119.2311
B14: Yes
B15: No | F15: Project IRR Sensitivity | Q15: %Change in Capex | R15: Equity IRR | S15: Project IRR | T15: Project NPV | U15: Equity NPV
F16: Selling Price (INR/t) | I16: 1280.2632 | J16: 1440.2961 | K16: 1520.3125 | L16: 1600.329 | M16: 1680.3454 | N16: 1760.3619 | O16: 1920.3948 | R16: 0.11436347 | S16: 0.1132572 | T16: 316.35859 | U16: 301.84625
B17: Refund of GST Credit | C17: No | F17: Capital (INR Cr) | H17: 0.1132572 | I17: -0.2 | J17: -0.1 | K17: -0.05 | L17: 0 | M17: 0.05 | N17: 0.1 | O17: 0.2 | Q17: -0.2 | R17: 0.14372199 | S17: 0.13889172 | T17: 792.95658 | U17: 781.3467
C18: P-IRR | D18: E-IRR | G18: 3424.3802 | H18: -0.2 | I18: 0.098657608 | J18: 0.1197446 | K18: 0.12952438 | L18: 0.13889172 | M18: 0.14789711 | N18: 0.15658129 | O18: 0.17311409 | Q18: -0.15 | R18: 0.13542599 | S18: 0.13167144 | T18: 673.80708 | U18: 661.47159
G19: 3852.4277 | H19: -0.1 | I19: 0.086882366 | J19: 0.10689978 | K19: 0.11617022 | L19: 0.12504237 | M19: 0.13356583 | N19: 0.14178061 | O19: 0.15740969 | Q19: -0.1 | R19: 0.12782759 | S19: 0.12504237 | T19: 554.65758 | U19: 541.59648
B20: Yes | G20: 4066.4514 | H20: -0.05 | I20: 0.081630536 | J20: 0.10121972 | K20: 0.11026898 | L20: 0.11892588 | M20: 0.12723961 | N20: 0.13524986 | O20: 0.15048445 | Q20: -0.05 | R20: 0.12083258 | S20: 0.11892588 | T20: 435.50809 | U20: 421.72136
B21: No | G21: 4280.4752 | H21: 0 | I21: 0.076714511 | J21: 0.095951181 | K21: 0.1047977 | L21: 0.1132572 | M21: 0.1213785 | N21: 0.12920097 | O21: 0.14407296 | Q21: 0 | R21: 0.11436347 | S21: 0.1132572 | T21: 316.35859 | U21: 301.84625
G22: 4494.499 | H22: 0.05 | I22: 0.072134626 | J22: 0.091044836 | K22: 0.099704758 | L22: 0.10798251 | M22: 0.11592654 | N22: 0.12357594 | O22: 0.13811344 | Q22: 0.05 | R22: 0.10835588 | S22: 0.10798251 | T22: 197.20909 | U22: 181.97113
G23: 4708.5227 | H23: 0.1 | I23: 0.067852459 | J23: 0.086459298 | K23: 0.09494683 | L23: 0.10305662 | M23: 0.11083677 | N23: 0.11832609 | O23: 0.13255399 | Q23: 0.1 | R23: 0.10275589 | S23: 0.10305662 | T23: 78.059592 | U23: 62.096016
G24: 5136.5702 | H24: 0.2 | I24: 0.060056165 | J24: 0.078060953 | K24: 0.086294834 | L24: 0.094104003 | M24: 0.10159072 | N24: 0.10879326 | O24: 0.12246599 | Q24: 0.15 | R24: 0.097517949 | S24: 0.098441313 | T24: -41.089906 | U24: -57.779099
Q25: 0.2 | R25: 0.092603293 | S25: 0.094104003 | T25: -160.2394 | U25: -177.65421
F27: Project IRR Sensitivity | Q27: %Change in Operating Cost | R27: Equity IRR | S27: Project IRR | T27: Project NPV | U27: Equity NPV
F28: Selling Price (INR/t) | I28: 1280.2632 | J28: 1440.2961 | K28: 1520.3125 | L28: 1600.329 | M28: 1680.3454 | N28: 1760.3619 | O28: 1920.3948 | R28: 0.11436347 | S28: 0.1132572 | T28: 316.35859 | U28: 301.84625
F29: Operating Cost (INR/t) | H29: 0.1132572 | I29: -0.2 | J29: -0.1 | K29: -0.05 | L29: 0 | M29: 0.05 | N29: 0.1 | O29: 0.2 | Q29: -0.2 | R29: 0.14140877 | S29: 0.13686179 | T29: 930.90751 | U29: 916.39517
G30: 677.34774 | H30: -0.2 | I30: 0.10198189 | J30: 0.12014994 | K30: 0.12866413 | L30: 0.13686179 | M30: 0.14477728 | N30: 0.15243907 | O30: 0.16709329 | Q30: -0.15 | R30: 0.1348845 | S30: 0.13118824 | T30: 777.27028 | U30: 762.75794
G31: 762.01621 | H31: -0.1 | I31: 0.089839736 | J31: 0.1084117 | K31: 0.117065 | L31: 0.12537157 | M31: 0.13337183 | N31: 0.14109888 | O31: 0.1558386 | Q31: -0.1 | R31: 0.12821116 | S31: 0.12537157 | T31: 623.63305 | U31: 609.12071
G32: 804.35044 | H32: -0.05 | I32: 0.083453134 | J32: 0.10228078 | K32: 0.11102274 | L32: 0.11939934 | M32: 0.12745485 | N32: 0.13522523 | O32: 0.15002433 | Q32: -0.05 | R32: 0.12137583 | S32: 0.11939934 | T32: 469.99582 | U32: 455.48348
G33: 846.68467 | H33: 0 | I33: 0.076714511 | J33: 0.095951181 | K33: 0.1047977 | L33: 0.1132572 | M33: 0.1213785 | N33: 0.12920097 | O33: 0.14407296 | Q33: 0 | R33: 0.11436347 | S33: 0.1132572 | T33: 316.35859 | U33: 301.84625
G34: 889.01891 | H34: 0.05 | I34: 0.069700699 | J34: 0.089400645 | K34: 0.098370733 | L34: 0.10692842 | M34: 0.11512797 | N34: 0.12301283 | O34: 0.13797354 | Q34: 0.05 | R34: 0.10715643 | S34: 0.10692842 | T34: 162.72136 | U34: 148.20902
G35: 931.35314 | H35: 0.1 | I35: 0.062365781 | J35: 0.082602566 | K35: 0.091719171 | L35: 0.10039334 | M35: 0.10868599 | N35: 0.11664542 | O35: 0.1317135 | Q35: 0.1 | R35: 0.099733809 | S35: 0.10039334 | T35: 9.0841276 | U35: -5.4282146
B36: Coal Mining Machinery | C36: Surface Miner | G36: 1016.0216 | H36: 0.2 | I36: 0.046494507 | J36: 0.067897141 | K36: 0.077558299 | L36: 0.086606485 | M36: 0.095142536 | N36: 0.10329773 | O36: 0.11865106 | Q36: 0.15 | R36: 0.092070592 | S36: 0.093628671 | T36: -144.5531 | U36: -159.06544
C37: P-IRR | D37: E-IRR | Q37: 0.2 | R37: 0.084136521 | S37: 0.086606485 | T37: -298.19033 | U37: -312.70267
B39: Surface Miner
B40: Shovel & Dumper
B42: Mining Operation | C42: Departmental
C43: P-IRR | D43: E-IRR
B45: Departmental
...

Sheet P&L
G5: ='Production Schedule'!E1 -> 46023 | H5: ='Production Schedule'!F1 -> 46389 | I5: ='Production Schedule'!G1 -> 46755 | J5: ='Production Schedule'!H1 -> 47121 | K5: ='Production Schedule'!I1 -> 47487 | L5: ='Production Schedule'!J1 -> 47853 | M5: ='Production Schedule'!K1 -> 48219 | N5: ='Production Schedule'!L1 -> 48585 | ... AC5: ='Production Schedule'!AA1 -> 54075
C6: Year No. | G6: ='Production Schedule'!E3 -> -4 | H6: ='Production Schedule'!F3 -> -3 | I6: ='Production Schedule'!G3 -> -2 | J6: ='Production Schedule'!H3 -> -1 | K6: ='Production Schedule'!I3 -> 1 | L6: ='Production Schedule'!J3 -> 2 | M6: ='Production Schedule'!K3 -> 3 | N6: ='Production Schedule'!L3 -> 4 | ... AC6: ='Production Schedule'!AA3 -> 19 | AK6: ='Production Schedule'!AI3 -> 0 | AL6: ='Production Schedule'!AJ3 -> 0 | AM6: ='Production Schedule'!AK3 -> 0 | AN6: ='Production Schedule'!AL3 -> 0 | AO6: ='Production Schedule'!AM3 -> 0 | AP6: ='Production Schedule'!AN3 -> 0
C7: Sales Products
A8: assuming 100% sold | C8: Total Product | D8: (Mt) | E8: =SUM(G8:AP8) -> 225.70441 | G8: ='Production Schedule'!E5 -> 0 | H8: ='Production Schedule'!F5 -> 0 | I8: ='Production Schedule'!G5 -> 0 | J8: ='Production Schedule'!H5 -> 0 | K8: ='Production Schedule'!I5 -> 1.9999998 | L8: ='Production Schedule'!J5 -> 3.9999987 | M8: ='Production Schedule'!K5 -> 8.0000007 | N8: ='Production Schedule'!L5 -> 11.999999 | ... AC8: ='Production Schedule'!AA5 -> 2.2043909
C9: Revenue
C10: Gross Revenue | D10: (INR Cr) | E10: =+SUM(G10:AP10) -> 35929.111 | G10: =Government!E8+Government!E9 -> 0 | H10: =Government!F8+Government!F9 -> 0 | I10: =Government!G8+Government!G9 -> 0 | J10: =Government!H8+Government!H9 -> 0 | K10: =Government!I8+Government!I9 -> 330.23996 | L10: =Government!J8+Government!J9 -> 660.47978 | M10: =Government!K8+Government!K9 -> 1320.9601 | N10: =Government!L8+Government!L9 -> 1981.4398 | ... AC10: =Government!AA8+Government!AA9 -> 363.98903
C11: Profit & Loss Statement
C12: Realisation | D12: (INR Cr) | E12: =+SUM(G12:AP12) -> 35929.111 | F12: =E12/$E$8*10 -> 1591.8658 | G12: =G10 -> 0 | H12: =H10 -> 0 | I12: =I10 -> 0 | J12: =J10 -> 0 | K12: =K10 -> 330.23996 | L12: =L10 -> 660.47978 | M12: =M10 -> 1320.9601 | N12: =N10 -> 1981.4398 | ... AC12: =AC10 -> 363.98903
C14: Less : Cost
C15: Operating Cost | D15: (INR Cr) | E15: =+SUM(G15:AP15) -> 23147.947 | F15: =E15/$E$8*10 -> 1025.5868 | G15: =SUM(G17:G18)*(1+Sensitivity!$C$5) -> 0 | H15: =SUM(H17:H18)*(1+Sensitivity!$C$5) -> 0 | I15: =SUM(I17:I18)*(1+Sensitivity!$C$5) -> 0 | J15: =SUM(J17:J18)*(1+Sensitivity!$C$5) -> 0 | K15: =SUM(K17:K18)*(1+Sensitivity!$C$5) -> 258.82253 | L15: =SUM(L17:L18)*(1+Sensitivity!$C$5) -> 364.52803 | M15: =SUM(M17:M18)*(1+Sensitivity!$C$5) -> 664.51221 | N15: =SUM(N17:N18)*(1+Sensitivity!$C$5) -> 1161.1992 | ... AC15: =SUM(AC17:AC18)*(1+Sensitivity!$C$5) -> 276.34771
C16: Fixed Cost
C17: Operating Cost | D17: INR Cr | E17: =+SUM(G17:AP17) -> 19830.447 | F17: =E17/$E$8*10 -> 878.60256 | G17: ='Project OPEX'!E100 -> 0 | H17: ='Project OPEX'!F100 -> 0 | I17: ='Project OPEX'!G100 -> 0 | J17: ='Project OPEX'!H100 -> 0 | K17: ='Project OPEX'!I100 -> 258.82253 | L17: ='Project OPEX'!J100 -> 334.82803 | M17: ='Project OPEX'!K100 -> 620.51221 | N17: ='Project OPEX'!L100 -> 1073.1992 | ... AC17: ='Project OPEX'!AA100 -> 276.34771
C18: Cost of Purchased Coal | D18: INR Cr | E18: =+SUM(G18:AP18) -> 3317.5 | F18: =E18/$E$8*10 -> 146.98428 | G18: ='Coal Price'!E10 -> 0 | H18: ='Coal Price'!F10 -> 0 | I18: ='Coal Price'!G10 -> 0 | J18: ='Coal Price'!H10 -> 0 | K18: ='Coal Price'!I10 -> 0 | L18: ='Coal Price'!J10 -> 29.7 | M18: ='Coal Price'!K10 -> 44 | N18: ='Coal Price'!L10 -> 88 | ... AC18: ='Coal Price'!AA10 -> 0
C21: Total Cost | D21: (INR Cr) | E21: =+SUM(G21:AP21) -> 23147.947 | F21: =E21/$E$8*10 -> 1025.5868 | G21: =G15 -> 0 | H21: =H15 -> 0 | I21: =I15 -> 0 | J21: =J15 -> 0 | K21: =K15 -> 258.82253 | L21: =L15 -> 364.52803 | M21: =M15 -> 664.51221 | N21: =N15 -> 1161.1992 | ... AC21: =AC15 -> 276.34771
C23: EBIDTA | D23: (INR Cr) | E23: =+SUM(G23:AP23) -> 12781.165 | F23: =E23/$E$8*10 -> 566.27892 | G23: =+G12-G21 -> 0 | H23: =+H12-H21 -> 0 | I23: =+I12-I21 -> 0 | J23: =+J12-J21 -> 0 | K23: =+K12-K21 -> 71.417433 | L23: =+L12-L21 -> 295.95175 | M23: =+M12-M21 -> 656.44791 | N23: =+N12-N21 -> 820.24052 | ... AC23: =+AC12-AC21 -> 87.641319
C24: EBIDTA % | E24: =+E23/E12 -> 0.35573283 | G24: =+IFERROR(G23/G12,"") | H24: =+IFERROR(H23/H12,"") | I24: =+IFERROR(I23/I12,"") | J24: =+IFERROR(J23/J12,"") | K24: =+IFERROR(K23/K12,"") -> 0.21625921 | L24: =+IFERROR(L23/L12,"") -> 0.44808601 | M24: =+IFERROR(M23/M12,"") -> 0.49694756 | N24: =+IFERROR(N23/N12,"") -> 0.41396188 | ... AC24: =+IFERROR(AC23/AC12,"") -> 0.24078011
C26: Less : Depreciation (Straight Line) | D26: (INR Cr) | E26: =+SUM(G26:AM26) -> -4934.6654 | F26: =E26/$E$8*10 -> -218.63399 | G26: =-'Depreciation-Owner'!H114 -> -14.631973 | H26: =-'Depreciation-Owner'!I114 -> -32.036732 | I26: =-'Depreciation-Owner'!J114 -> -66.593835 | J26: =-'Depreciation-Owner'!K114 -> -97.214807 | K26: =-'Depreciation-Owner'!L114 -> -135.14873 | L26: =-'Depreciation-Owner'!M114 -> -144.59207 | M26: =-'Depreciation-Owner'!N114 -> -161.45289 | N26: =-'Depreciation-Owner'!O114 -> -207.49698 | ... AC26: =-'Depreciation-Owner'!AD114 -> -250.9493
C27: Add: Salvage Value | D27: (INR Cr) | E27: =+SUM(G27:AM27) -> 1499.0601 | F27: =E27/$E$8*10 -> 66.416961 | AC27: ='Depreciation-Owner'!AD46+'Depreciation-Owner'!AD52+'Depreciation-Owner'!AD58+'Depreciation-Owner'!AD64+'Depreciation-Owner'!AD70+'Depreciation-Owner'!AD76+'Depreciation-Owner'!AD82+'Depreciation-Owner'!AD88+'Depreciation-Owner'!AD94+'Depreciation-Owner'!AD100+'Depreciation-Owner'!AD106+'Depreciation-Owner'!AD112 -> 1499.0601
C29: EBIT | D29: (INR Cr) | E29: =+SUM(G29:AM29) -> 9345.5593 | F29: =E29/$E$8*10 -> 414.06189 | G29: =+G23+G26+G27 -> -14.631973 | H29: =+H23+H26+H27 -> -32.036732 | I29: =+I23+I26+I27 -> -66.593835 | J29: =+J23+J26+J27 -> -97.214807 | K29: =+K23+K26+K27 -> -63.731295 | L29: =+L23+L26+L27 -> 151.35968 | M29: =+M23+M26+M27 -> 494.99501 | N29: =+N23+N26+N27 -> 612.74354 | ... AC29: =+AC23+AC26+AC27 -> 1335.7521
C31: Less : Interest | D31: (INR Cr) | E31: =+SUM(G31:AM31) -> 0 | F31: =E31/$E$8*10 -> 0 | G31: =-'Borrowings-Owner'!G96 -> 0 | H31: =-'Borrowings-Owner'!H96 -> 0 | I31: =-'Borrowings-Owner'!I96 -> 0 | J31: =-'Borrowings-Owner'!J96 -> 0 | K31: =-'Borrowings-Owner'!K96 -> 0 | L31: =-'Borrowings-Owner'!L96 -> 0 | M31: =-'Borrowings-Owner'!M96 -> 0 | N31: =-'Borrowings-Owner'!N96 -> 0 | ... AC31: =-'Borrowings-Owner'!AC96 -> 0
C33: EBT | D33: (INR Cr) | E33: =+SUM(G33:AM33) -> 9345.5593 | F33: =E33/$E$8*10 -> 414.06189 | G33: =+G29+G31 -> -14.631973 | H33: =+H29+H31 -> -32.036732 | I33: =+I29+I31 -> -66.593835 | J33: =+J29+J31 -> -97.214807 | K33: =+K29+K31 -> -63.731295 | L33: =+L29+L31 -> 151.35968 | M33: =+M29+M31 -> 494.99501 | N33: =+N29+N31 -> 612.74354 | ... AC33: =+AC29+AC31 -> 1335.7521
H34: =IFERROR(H33/#REF!,"") | I34: =IFERROR(I33/#REF!,"") | J34: =IFERROR(J33/#REF!,"")
C35: Less : Tax | D35: (INR Cr) | E35: =+SUM(G35:AM35) -> 0 | F35: =E35/$E$8*10 -> 0 | G35: =-Tax!F14 -> 0 | H35: =-Tax!G14 -> 0 | I35: =-Tax!H14 -> 0 | J35: =-Tax!I14 -> 0 | K35: =-Tax!J14 -> 0 | L35: =-Tax!K14 -> 0 | M35: =-Tax!L14 -> 0 | N35: =-Tax!M14 -> 0 | ... AC35: =-Tax!AB14 -> 0
C37: PAT | D37: (INR Cr) | E37: =+SUM(G37:AM37) -> 9345.5593 | F37: =E37/$E$8*10 -> 414.06189 | G37: =+G33+G35 -> -14.631973 | H37: =+H33+H35 -> -32.036732 | I37: =+I33+I35 -> -66.593835 | J37: =+J33+J35 -> -97.214807 | K37: =+K33+K35 -> -63.731295 | L37: =+L33+L35 -> 151.35968 | M37: =+M33+M35 -> 494.99501 | N37: =+N33+N35 -> 612.74354 | ... AC37: =+AC33+AC35 -> 1335.7521
C39: CSR Spend per Companies Act | D39: (INR Cr) | E39: =+SUM(G39:AM39) -> -201.24745 | F39: =E39/$E$8*10 -> -8.9164165 | G39: =-IF(G37<0,0,G37*$C$40) -> 0 | H39: =-IF(H37<0,0,H37*$C$40) -> 0 | I39: =-IF(I37<0,0,I37*$C$40) -> 0 | J39: =-IF(J37<0,0,J37*$C$40) -> 0 | K39: =-IF(K37<0,0,K37*$C$40) -> 0 | L39: =-IF(L37<0,0,L37*$C$40) -> -3.0271936 | M39: =-IF(M37<0,0,M37*$C$40) -> -9.8999003 | N39: =-IF(N37<0,0,N37*$C$40) -> -12.254871 | ... AC39: =-IF(AC37<0,0,AC37*$C$40) -> -26.715042
C40: =Assumptions_Dashboard!D132 -> 0.02 | D40: (INR Cr)
C41: PAT after CSR spent | D41: (INR Cr) | E41: =+SUM(G41:AM41) -> 9144.3119 | F41: =E41/$E$8*10 -> 405.14547 | G41: =+G37+G39 -> -14.631973 | H41: =+H37+H39 -> -32.036732 | I41: =+I37+I39 -> -66.593835 | J41: =+J37+J39 -> -97.214807 | K41: =+K37+K39 -> -63.731295 | L41: =+L37+L39 -> 148.33248 | M41: =+M37+M39 -> 485.09511 | N41: =+N37+N39 -> 600.48867 | ... AC41: =+AC37+AC39 -> 1309.0371

Sheet CF
F2: ='P&L'!G5 -> 46023 | G2: ='P&L'!H5 -> 46389 | H2: ='P&L'!I5 -> 46755 | I2: ='P&L'!J5 -> 47121 | J2: ='P&L'!K5 -> 47487 | K2: ='P&L'!L5 -> 47853 | L2: ='P&L'!M5 -> 48219 | M2: ='P&L'!N5 -> 48585 | ... AB2: ='P&L'!AC5 -> 54075
C3: Year No. | F3: ='P&L'!G6 -> -4 | G3: ='P&L'!H6 -> -3 | H3: ='P&L'!I6 -> -2 | I3: ='P&L'!J6 -> -1 | J3: ='P&L'!K6 -> 1 | K3: ='P&L'!L6 -> 2 | L3: ='P&L'!M6 -> 3 | M3: ='P&L'!N6 -> 4 | ... AB3: ='P&L'!AC6 -> 19 | AJ3: ='P&L'!AK6 -> 0 | AK3: ='P&L'!AL6 -> 0 | AL3: ='P&L'!AM6 -> 0 | AM3: ='P&L'!AN6 -> 0
C5: Project Cash Inflow
C6: Realisation | D6: (INR Cr) | E6: =SUM(F6:AM6) -> 35929.111 | F6: ='P&L'!G12 -> 0 | G6: ='P&L'!H12 -> 0 | H6: ='P&L'!I12 -> 0 | I6: ='P&L'!J12 -> 0 | J6: ='P&L'!K12 -> 330.23996 | K6: ='P&L'!L12 -> 660.47978 | L6: ='P&L'!M12 -> 1320.9601 | M6: ='P&L'!N12 -> 1981.4398 | ... AB6: ='P&L'!AC12 -> 363.98903
C7: Total Cash In-Flow | D7: (INR Cr) | E7: =SUM(F7:AM7) -> 35929.111 | F7: =SUM(F6:F6) -> 0 | G7: =SUM(G6:G6) -> 0 | H7: =SUM(H6:H6) -> 0 | I7: =SUM(I6:I6) -> 0 | J7: =SUM(J6:J6) -> 330.23996 | K7: =SUM(K6:K6) -> 660.47978 | L7: =SUM(L6:L6) -> 1320.9601 | M7: =SUM(M6:M6) -> 1981.4398 | ... AB7: =SUM(AB6:AB6) -> 363.98903
C8: Project Cash Outflow
C9: Operating Cost | D9: (INR Cr) | E9: =SUM(F9:AM9) -> -23147.947 | F9: =-'P&L'!G15 -> 0 | G9: =-'P&L'!H15 -> 0 | H9: =-'P&L'!I15 -> 0 | I9: =-'P&L'!J15 -> 0 | J9: =-'P&L'!K15 -> -258.82253 | K9: =-'P&L'!L15 -> -364.52803 | L9: =-'P&L'!M15 -> -664.51221 | M9: =-'P&L'!N15 -> -1161.1992 | ... AB9: =-'P&L'!AC15 -> -276.34771
C10: Capex | D10: (INR Cr) | E10: =SUM(F10:AM10) -> -6433.7255 | F10: =-'Depreciation-Owner'!H35 -> -155.9943 | G10: =-'Depreciation-Owner'!I35 -> -343.46765 | H10: =-'Depreciation-Owner'!J35 -> -677.7139 | I10: =-'Depreciation-Owner'!K35 -> -542.15415 | J10: =-'Depreciation-Owner'!L35 -> -512.0367 | K10: =-'Depreciation-Owner'!M35 -> -185.81301 | L10: =-'Depreciation-Owner'!N35 -> -214.02863 | M10: =-'Depreciation-Owner'!O35 -> -587.76578 | ... AB10: =-'Depreciation-Owner'!AD35 -> -180.57944
C11: Taxes | D11: (INR Cr) | E11: =SUM(F11:AM11) -> 0 | F11: =-Tax!F14 -> 0 | G11: =-Tax!G14 -> 0 | H11: =-Tax!H14 -> 0 | I11: =-Tax!I14 -> 0 | J11: =-Tax!J14 -> 0 | K11: =-Tax!K14 -> 0 | L11: =-Tax!L14 -> 0 | M11: =-Tax!M14 -> 0 | ... AB11: =-Tax!AB14 -> 0
C12: Total Cash Out-Flow | D12: (INR Cr) | E12: =SUM(F12:AM12) -> -29581.672 | F12: =SUM(F9:F11) -> -155.9943 | G12: =SUM(G9:G11) -> -343.46765 | H12: =SUM(H9:H11) -> -677.7139 | I12: =SUM(I9:I11) -> -542.15415 | J12: =SUM(J9:J11) -> -770.85922 | K12: =SUM(K9:K11) -> -550.34104 | L12: =SUM(L9:L11) -> -878.54085 | M12: =SUM(M9:M11) -> -1748.965 | ... AB12: =SUM(AB9:AB11) -> -456.92715
C13: Free Cash flow for Project
C14: Project Cashflow | D14: (INR Cr) | E14: =SUM(F14:AM14) -> 6347.4392 | F14: =F7+F12 -> -155.9943 | G14: =G7+G12 -> -343.46765 | H14: =H7+H12 -> -677.7139 | I14: =I7+I12 -> -542.15415 | J14: =J7+J12 -> -440.61926 | K14: =K7+K12 -> 110.13874 | L14: =L7+L12 -> 442.41927 | M14: =M7+M12 -> 232.47474 | ... AB14: =AB7+AB12 -> -92.938121
C15: Cummulative Cashflow | D15: (INR Cr) | F15: =F14 -> -155.9943 | G15: =F15+G14 -> -499.46195 | H15: =G15+H14 -> -1177.1758 | I15: =H15+I14 -> -1719.33 | J15: =I15+J14 -> -2159.9493 | K15: =J15+K14 -> -2049.8105 | L15: =K15+L14 -> -1607.3912 | M15: =L15+M14 -> -1374.9165 | N15: =M15+N14 -> -638.92615 | ... AB15: =AA15+AB14 -> 6347.4392
C18: Project IRR | D18: =IFERROR(IRR(F14:AB14),"-") -> 0.15815964
C19: Project NPV | D19: =NPV(E19,F14:AB14) -> 900.32264 | E19: 0.1
C20: Payback | D20: =COUNTIF(F15:AI15,"<0")+INDEX(F21:AI21,COUNTIF(F21:AI21,"<0")+1) -> 10 | E20: from Now
D21: =COUNTIF(F15:AI15,"<0")+INDEX(F21:AI21,COUNTIF(F21:AI21,"<0")+1)-COUNT(F15:I15) -> 6 | E21: from Start of Production | F21: =IF(F14<0,0,IFERROR(IF(F15<0,0,ABS(F15)/F14),0)) -> 0 | G21: =IF(G14<0,0,IFERROR(IF(G15<0,0,ABS(G15)/G14),0)) -> 0 | H21: =IF(H14<0,0,IFERROR(IF(H15<0,0,ABS(H15)/H14),0)) -> 0 | I21: =IF(I14<0,0,IFERROR(IF(I15<0,0,ABS(I15)/I14),0)) -> 0 | J21: =IF(J14<0,0,IFERROR(IF(J15<0,0,ABS(J15)/J14),0)) -> 0 | K21: =IF(K14<0,0,IFERROR(IF(K15<0,0,ABS(K15)/K14),0)) -> 0 | L21: =IF(L14<0,0,IFERROR(IF(L15<0,0,ABS(L15)/L14),0)) -> 0 | M21: =IF(M14<0,0,IFERROR(IF(M15<0,0,ABS(M15)/M14),0)) -> 0 | ... AB21: =IF(AB14<0,0,IFERROR(IF(AB15<0,0,ABS(AB15)/AB14),0)) -> 0
C24: Equity Cash Inflow
C25: Realisation | D25: (INR Cr) | E25: =SUM(F25:AM25) -> 35929.111 | F25: =F6 -> 0 | G25: =G6 -> 0 | H25: =H6 -> 0 | I25: =I6 -> 0 | J25: =J6 -> 330.23996 | K25: =K6 -> 660.47978 | L25: =L6 -> 1320.9601 | M25: =M6 -> 1981.4398 | ... AB25: =AB6 -> 363.98903
C26: Borrowing | D26: (INR Cr) | E26: =SUM(F26:AM26) -> 0 | F26: ='Borrowings-Owner'!G23+'Borrowings-Owner'!G67+'Borrowings-Owner'!G88 -> 0 | G26: ='Borrowings-Owner'!H23+'Borrowings-Owner'!H67+'Borrowings-Owner'!H88 -> 0 | H26: ='Borrowings-Owner'!I23+'Borrowings-Owner'!I67+'Borrowings-Owner'!I88 -> 0 | I26: ='Borrowings-Owner'!J23+'Borrowings-Owner'!J67+'Borrowings-Owner'!J88 -> 0 | J26: ='Borrowings-Owner'!K23+'Borrowings-Owner'!K67+'Borrowings-Owner'!K88 -> 0 | K26: ='Borrowings-Owner'!L23+'Borrowings-Owner'!L67+'Borrowings-Owner'!L88 -> 0 | L26: ='Borrowings-Owner'!M23+'Borrowings-Owner'!M67+'Borrowings-Owner'!M88 -> 0 | M26: ='Borrowings-Owner'!N23+'Borrowings-Owner'!N67+'Borrowings-Owner'!N88 -> 0 | ... AB26: ='Borrowings-Owner'!AC23+'Borrowings-Owner'!AC67+'Borrowings-Owner'!AC88 -> 0
C27: Total Cash In-Flow | D27: (INR Cr) | E27: =SUM(F27:AM27) -> 35929.111 | F27: =SUM(F25:F26) -> 0 | G27: =SUM(G25:G26) -> 0 | H27: =SUM(H25:H26) -> 0 | I27: =SUM(I25:I26) -> 0 | J27: =SUM(J25:J26) -> 330.23996 | K27: =SUM(K25:K26) -> 660.47978 | L27: =SUM(L25:L26) -> 1320.9601 | M27: =SUM(M25:M26) -> 1981.4398 | ... AB27: =SUM(AB25:AB26) -> 363.98903
C28: Equity Cash Outflow
C29: Operating Cost | D29: (INR Cr) | E29: =SUM(F29:AM29) -> -23147.947 | F29: =F9 -> 0 | G29: =G9 -> 0 | H29: =H9 -> 0 | I29: =I9 -> 0 | J29: =J9 -> -258.82253 | K29: =K9 -> -364.52803 | L29: =L9 -> -664.51221 | M29: =M9 -> -1161.1992 | ... AB29: =AB9 -> -276.34771
C30: Capex | D30: (INR Cr) | E30: =SUM(F30:AM30) -> -6433.7255 | F30: =F10 -> -155.9943 | G30: =G10 -> -343.46765 | H30: =H10 -> -677.7139 | I30: =I10 -> -542.15415 | J30: =J10 -> -512.0367 | K30: =K10 -> -185.81301 | L30: =L10 -> -214.02863 | M30: =M10 -> -587.76578 | ... AB30: =AB10 -> -180.57944
C31: Taxes | D31: (INR Cr) | E31: =SUM(F31:AM31) -> 0 | F31: =-Tax!F14 -> 0 | G31: =-Tax!G14 -> 0 | H31: =-Tax!H14 -> 0 | I31: =-Tax!I14 -> 0 | J31: =-Tax!J14 -> 0 | K31: =-Tax!K14 -> 0 | L31: =-Tax!L14 -> 0 | M31: =-Tax!M14 -> 0 | ... AB31: =-Tax!AB14 -> 0
C32: Interest | D32: (INR Cr) | E32: =SUM(F32:AM32) -> 0 | F32: ='P&L'!G31 -> 0 | G32: ='P&L'!H31 -> 0 | H32: ='P&L'!I31 -> 0 | I32: ='P&L'!J31 -> 0 | J32: ='P&L'!K31 -> 0 | K32: ='P&L'!L31 -> 0 | L32: ='P&L'!M31 -> 0 | M32: ='P&L'!N31 -> 0 | ... AB32: ='P&L'!AC31 -> 0
C33: Repayment | D33: (INR Cr) | E33: =SUM(F33:AM33) -> 0 | F33: =-('Borrowings-Owner'!G24+'Borrowings-Owner'!G68+'Borrowings-Owner'!G89) -> 0 | G33: =-('Borrowings-Owner'!H24+'Borrowings-Owner'!H68+'Borrowings-Owner'!H89) -> 0 | H33: =-('Borrowings-Owner'!I24+'Borrowings-Owner'!I68+'Borrowings-Owner'!I89) -> 0 | I33: =-('Borrowings-Owner'!J24+'Borrowings-Owner'!J68+'Borrowings-Owner'!J89) -> 0 | J33: =-('Borrowings-Owner'!K24+'Borrowings-Owner'!K68+'Borrowings-Owner'!K89) -> 0 | K33: =-('Borrowings-Owner'!L24+'Borrowings-Owner'!L68+'Borrowings-Owner'!L89) -> 0 | L33: =-('Borrowings-Owner'!M24+'Borrowings-Owner'!M68+'Borrowings-Owner'!M89) -> 0 | M33: =-('Borrowings-Owner'!N24+'Borrowings-Owner'!N68+'Borrowings-Owner'!N89) -> 0 | ... AB33: =-('Borrowings-Owner'!AC24+'Borrowings-Owner'!AC68+'Borrowings-Owner'!AC89) -> 0
C34: Total Cash Out-Flow | D34: (INR Cr) | E34: =SUM(F34:AM34) -> -29581.672 | F34: =SUM(F29:F33) -> -155.9943 | G34: =SUM(G29:G33) -> -343.46765 | H34: =SUM(H29:H33) -> -677.7139 | I34: =SUM(I29:I33) -> -542.15415 | J34: =SUM(J29:J33) -> -770.85922 | K34: =SUM(K29:K33) -> -550.34104 | L34: =SUM(L29:L33) -> -878.54085 | M34: =SUM(M29:M33) -> -1748.965 | ... AB34: =SUM(AB29:AB33) -> -456.92715
C35: Free Cash flow for Equity Shareholder
C36: Equity Shareholder Cashflow | D36: (INR Cr) | E36: =SUM(F36:AM36) -> 6347.4392 | F36: =F27+F34 -> -155.9943 | G36: =G27+G34 -> -343.46765 | H36: =H27+H34 -> -677.7139 | I36: =I27+I34 -> -542.15415 | J36: =J27+J34 -> -440.61926 | K36: =K27+K34 -> 110.13874 | L36: =L27+L34 -> 442.41927 | M36: =M27+M34 -> 232.47474 | ... AB36: =AB27+AB34 -> -92.938121
C37: Cummulative Cashflow | D37: (INR Cr) | F37: =F36 -> -155.9943 | G37: =F37+G36 -> -499.46195 | H37: =G37+H36 -> -1177.1758 | I37: =H37+I36 -> -1719.33 | J37: =I37+J36 -> -2159.9493 | K37: =J37+K36 -> -2049.8105 | L37: =K37+L36 -> -1607.3912 | M37: =L37+M36 -> -1374.9165 | N37: =M37+N36 -> -638.92615 | ... AB37: =AA37+AB36 -> 6347.4392
C40: Equity IRR | D40: =IFERROR(IRR(F36:AB36),"-") -> 0.15815964
C41: Equity NPV | D41: =NPV(E41,F36:AB36) -> 900.32264 | E41: =E19 -> 0.1

Sheet Tax
F4: ='P&L'!G5 -> 46023 | G4: ='P&L'!H5 -> 46389 | H4: ='P&L'!I5 -> 46755 | I4: ='P&L'!J5 -> 47121 | J4: ='P&L'!K5 -> 47487 | K4: ='P&L'!L5 -> 47853 | L4: ='P&L'!M5 -> 48219 | M4: ='P&L'!N5 -> 48585 | ... AP4: ='P&L'!AQ5 -> 0
C5: Year No. | F5: ='P&L'!G6 -> -4 | G5: ='P&L'!H6 -> -3 | H5: ='P&L'!I6 -> -2 | I5: ='P&L'!J6 -> -1 | J5: ='P&L'!K6 -> 1 | K5: ='P&L'!L6 -> 2 | L5: ='P&L'!M6 -> 3 | M5: ='P&L'!N6 -> 4 | ... AP5: ='P&L'!AQ6 -> 0
C7: Normal Tax
C8: EBIDTA | D8: (INR Cr) | E8: =SUM(F8:AP8) -> 12781.165 | F8: ='P&L'!G23 -> 0 | G8: ='P&L'!H23 -> 0 | H8: ='P&L'!I23 -> 0 | I8: ='P&L'!J23 -> 0 | J8: ='P&L'!K23 -> 71.417433 | K8: ='P&L'!L23 -> 295.95175 | L8: ='P&L'!M23 -> 656.44791 | M8: ='P&L'!N23 -> 820.24052 | ... AI8: ='P&L'!AJ23 -> 0
C9: Less : Depreciation | D9: (INR Cr) | E9: =SUM(F9:AN9) -> #REF! | F9: ='Depreciation-Owner'!H114 -> 14.631973 | G9: ='Depreciation-Owner'!I114 -> 32.036732 | H9: ='Depreciation-Owner'!J114 -> 66.593835 | I9: ='Depreciation-Owner'!K114 -> 97.214807 | J9: ='Depreciation-Owner'!L114 -> 135.14873 | K9: ='Depreciation-Owner'!M114 -> 144.59207 | L9: ='Depreciation-Owner'!N114 -> 161.45289 | M9: ='Depreciation-Owner'!O114 -> 207.49698 | ... AB9: ='Depreciation-Owner'!AD114 -> 250.9493 | AC9: ='Depreciation-Owner'!#REF! -> #REF! | AD9: ='Depreciation-Owner'!#REF! -> #REF! | AE9: ='Depreciation-Owner'!#REF! -> #REF! | AF9: ='Depreciation-Owner'!#REF! -> #REF! | AG9: ='Depreciation-Owner'!#REF! -> #REF! | AH9: ='Depreciation-Owner'!#REF! -> #REF! | AI9: ='Depreciation-Owner'!#REF! -> #REF!
C10: Less : Interest | D10: (INR Cr) | E10: =SUM(F10:AN10) -> 0 | F10: =-'P&L'!G31 -> 0 | G10: =-'P&L'!H31 -> 0 | H10: =-'P&L'!I31 -> 0 | I10: =-'P&L'!J31 -> 0 | J10: =-'P&L'!K31 -> 0 | K10: =-'P&L'!L31 -> 0 | L10: =-'P&L'!M31 -> 0 | M10: =-'P&L'!N31 -> 0 | ... AI10: =-'P&L'!AJ31 -> 0
C11: EBT for normal tax | D11: (INR Cr) | E11: =SUM(F11:AN11) -> #REF! | F11: =+F8-SUM(F9:F10) -> -14.631973 | G11: =+G8-SUM(G9:G10) -> -32.036732 | H11: =+H8-SUM(H9:H10) -> -66.593835 | I11: =+I8-SUM(I9:I10) -> -97.214807 | J11: =+J8-SUM(J9:J10) -> -63.731295 | K11: =+K8-SUM(K9:K10) -> 151.35968 | L11: =+L8-SUM(L9:L10) -> 494.99501 | M11: =+M8-SUM(M9:M10) -> 612.74354 | ... AI11: =+AI8-SUM(AI9:AI10) -> #REF!
B14: =Assumptions_Dashboard!D128 -> 0.2517 | C14: Normal Tax | D14: (INR Cr) | E14: =SUM(F14:AN14) -> 0 | F14: =IF(Assumptions_Dashboard!$L$6="Yes",0,IF(F11<0,0,F11*$B$14)) -> 0 | G14: =IF(Assumptions_Dashboard!$L$6="Yes",0,IF(G11<0,0,G11*$B$14)) -> 0 | H14: =IF(Assumptions_Dashboard!$L$6="Yes",0,IF(H11<0,0,H11*$B$14)) -> 0 | I14: =IF(Assumptions_Dashboard!$L$6="Yes",0,IF(I11<0,0,I11*$B$14)) -> 0 | J14: =IF(Assumptions_Dashboard!$L$6="Yes",0,IF(J11<0,0,J11*$B$14)) -> 0 | K14: =IF(Assumptions_Dashboard!$L$6="Yes",0,IF(K11<0,0,K11*$B$14)) -> 0 | L14: =IF(Assumptions_Dashboard!$L$6="Yes",0,IF(L11<0,0,L11*$B$14)) -> 0 | M14: =IF(Assumptions_Dashboard!$L$6="Yes",0,IF(M11<0,0,M11*$B$14)) -> 0 | ... AI14: =IF(Assumptions_Dashboard!$L$6="Yes",0,IF(AI11<0,0,AI11*$B$14)) -> 0
I239: =(#REF!+#REF!*20%) -> #REF!

Sheet Borrowings-Owner
G1: ='Production Schedule'!E1 -> 46023 | H1: ='Production Schedule'!F1 -> 46389 | I1: ='Production Schedule'!G1 -> 46755 | J1: ='Production Schedule'!H1 -> 47121 | K1: ='Production Schedule'!I1 -> 47487 | L1: ='Production Schedule'!J1 -> 47853 | M1: ='Production Schedule'!K1 -> 48219 | N1: ='Production Schedule'!L1 -> 48585 | ... AC1: ='Production Schedule'!AA1 -> 54075
